Workbook

Sheet Summary
A1: Quality audit of seed_companies.csv
A2: Live summary - the counts below are formulas and update when the data sheet is edited.
A4: Records
A5: Delivered records | B5: =COUNTA('Leads'!A:A)-1
A6: Verified | B6: =COUNTIF('Leads'!W:W,"VERIFIED") | C6: =IF(B5=0,0,B6/B5)
A7: Partially verified | B7: =COUNTIF('Leads'!W:W,"PARTIALLY_VERIFIED") | C7: =IF(B5=0,0,B7/B5)
A8: Unverified | B8: =COUNTIF('Leads'!W:W,"UNVERIFIED") | C8: =IF(B5=0,0,B8/B5)
A9: Needs review | B9: =COUNTIF('Leads'!W:W,"NEEDS_REVIEW") | C9: =IF(B5=0,0,B9/B5)
A10: Extracted before merge/exclusion | B10: 10
A11: Duplicate groups | B11: 1
A12: Reviewer decisions recorded | B12: =COUNTA('Leads'!AI:AI)-1
A14: Field completeness | B14: Filled | C14: Share | D14: How it is verified
A15: Company name | B15: =COUNTA('Leads'!B:B)-1 | C15: =IF(B5=0,0,B15/B5) | D15: Present in the primary source; confirmed when found on the company's own website.
A16: Legal entity name | B16: =COUNTA('Leads'!C:C)-1 | C16: =IF(B5=0,0,B16/B5) | D16: Returned by the EU VIES VAT service for a valid VAT number.
A17: Category | B17: =COUNTA('Leads'!D:D)-1 | C17: =IF(B5=0,0,B17/B5)
A18: Subcategory | B18: =COUNTA('Leads'!E:E)-1 | C18: =IF(B5=0,0,B18/B5)
A19: Street | B19: =COUNTA('Leads'!F:F)-1 | C19: =IF(B5=0,0,B19/B5)
A20: No. | B20: =COUNTA('Leads'!G:G)-1 | C20: =IF(B5=0,0,B20/B5)
A21: Postcode | B21: =COUNTA('Leads'!H:H)-1 | C21: =IF(B5=0,0,B21/B5) | D21: Format checked for the project country.
A22: City | B22: =COUNTA('Leads'!I:I)-1 | C22: =IF(B5=0,0,B22/B5)
A23: District | B23: =COUNTA('Leads'!J:J)-1 | C23: =IF(B5=0,0,B23/B5)
A24: Country | B24: =COUNTA('Leads'!K:K)-1 | C24: =IF(B5=0,0,B24/B5)
A25: Phone | B25: =COUNTA('Leads'!L:L)-1 | C25: =IF(B5=0,0,B25/B5) | D25: Parsed and validated with libphonenumber; confirmed when the same number appears on the website.
A26: E-mail | B26: =COUNTA('Leads'!M:M)-1 | C26: =IF(B5=0,0,B26/B5) | D26: Syntax check + mail-domain (MX) lookup; confirmed when found on the company's website.
A27: Website | B27: =COUNTA('Leads'!N:N)-1 | C27: =IF(B5=0,0,B27/B5) | D27: Fetched live; confirmed when the company name appears on the page.
A28: LinkedIn | B28: =COUNTA('Leads'!O:O)-1 | C28: =IF(B5=0,0,B28/B5) | D28: Link found on the company's own website or supplied by the source.
A29: Facebook | B29: =COUNTA('Leads'!P:P)-1 | C29: =IF(B5=0,0,B29/B5)
A30: Instagram | B30: =COUNTA('Leads'!Q:Q)-1 | C30: =IF(B5=0,0,B30/B5)
A31: VAT number | B31: =COUNTA('Leads'!R:R)-1 | C31: =IF(B5=0,0,B31/B5) | D31: Checksum validated; existence and registered name checked with the EU VIES service.
A32: Opening hours | B32: =COUNTA('Leads'!S:S)-1 | C32: =IF(B5=0,0,B32/B5)
A33: Description | B33: =COUNTA('Leads'!T:T)-1 | C33: =IF(B5=0,0,B33/B5)
A34: Latitude | B34: =COUNTA('Leads'!U:U)-1 | C34: =IF(B5=0,0,B34/B5)
A35: Longitude | B35: =COUNTA('Leads'!V:V)-1 | C35: =IF(B5=0,0,B35/B5)
A37: Verification of key fields | B37: verified | C37: unverified | D37: conflict / invalid
A38: Company name check | B38: =COUNTIF('Leads'!Z:Z,"verified*") | C38: =COUNTIF('Leads'!Z:Z,"unverified*") | D38: =COUNTIF('Leads'!Z:Z,"conflict*")+COUNTIF('Leads'!Z:Z,"invalid*")
A39: Website check | B39: =COUNTIF('Leads'!AA:AA,"verified*") | C39: =COUNTIF('Leads'!AA:AA,"unverified*") | D39: =COUNTIF('Leads'!AA:AA,"conflict*")+COUNTIF('Leads'!AA:AA,"invalid*")
A40: E-mail check | B40: =COUNTIF('Leads'!AB:AB,"verified*") | C40: =COUNTIF('Leads'!AB:AB,"unverified*") | D40: =COUNTIF('Leads'!AB:AB,"conflict*")+COUNTIF('Leads'!AB:AB,"invalid*")
A41: Phone check | B41: =COUNTIF('Leads'!AC:AC,"verified*") | C41: =COUNTIF('Leads'!AC:AC,"unverified*") | D41: =COUNTIF('Leads'!AC:AC,"conflict*")+COUNTIF('Leads'!AC:AC,"invalid*")
A42: VAT number check | B42: =COUNTIF('Leads'!AD:AD,"verified*") | C42: =COUNTIF('Leads'!AD:AD,"unverified*") | D42: =COUNTIF('Leads'!AD:AD,"conflict*")+COUNTIF('Leads'!AD:AD,"invalid*")
A44: Sources
...

Sheet Leads
A1: Record ID | B1: Company name | C1: Legal entity name | D1: Category | E1: Subcategory | F1: Street | G1: No. | H1: Postcode | I1: City | J1: District | K1: Country | L1: Phone | M1: E-mail | N1: Website | O1: LinkedIn | P1: Facebook | Q1: Instagram | R1: VAT number | S1: Opening hours | T1: Description | U1: Latitude | V1: Longitude | W1: Verification status | X1: Review flags | Y1: Completeness % | Z1: Company name check | AA1: Website check | AB1: E-mail check | AC1: Phone check | AD1: VAT number check | AE1: Source | AF1: Source URL | AG1: Duplicate group | AH1: Extracted at (UTC) | AI1: Reviewer decision | AJ1: Reviewer notes
A2: ROW-0002 | B2: Hollywok | F2: President Kennedylaan 100 | H2: 8500 | I2: Kortrijk | L2: +32 56 20 55 88 | N2: https://hollywok.be/ | T2: met at trade fair, asked for a quote | W2: NEEDS_REVIEW | X2: duplicate group DUP-001: same phone; names 100% similar - review | Y2: 36.4 | Z2: unverified | AA2: unverified | AB2: missing | AC2: unverified | AD2: missing | AE2: seed_companies.csv | AG2: DUP-001 | AH2: 2026-09-08T09:01:00+00:00
A3: ROW-0003 | B3: Vesper | F3: Voorstraat 34 | H3: 8500 | I3: Kortrijk | M3: info@vesperkortrijk.be | W3: UNVERIFIED | Y3: 27.3 | Z3: unverified | AA3: missing | AB3: unverified | AC3: missing | AD3: missing | AE3: seed_companies.csv | AH3: 2026-09-08T09:01:00+00:00
A4: ROW-0004 | B4: Basta! | F4: Havermarkt 3 | H4: 8500 | I4: Kortrijk | L4: +32 56 49 37 49 | N4: https://www.bastakortrijk.be/ | W4: UNVERIFIED | Y4: 31.8 | Z4: unverified | AA4: unverified | AB4: missing | AC4: unverified | AD4: missing | AE4: seed_companies.csv | AH4: 2026-09-08T09:01:00+00:00
A5: ROW-0005 | B5: Bowls Asian Cuisine | F5: Dolfijnkaai 12 | H5: 8500 | I5: Kortrijk | L5: +32 56 19 81 99 | M5: eat@bowls-kortrijk.be | N5: https://www.bowls-kortrijk.be/ | W5: UNVERIFIED | Y5: 36.4 | Z5: unverified | AA5: unverified | AB5: unverified | AC5: unverified | AD5: missing | AE5: seed_companies.csv | AH5: 2026-09-08T09:01:00+00:00
A6: ROW-0006 | B6: Dionysos | F6: Doornikselaan 4 | H6: 8500 | I6: Kortrijk | T6: no website known - please research | W6: UNVERIFIED | Y6: 27.3 | Z6: unverified | AA6: missing | AB6: missing | AC6: missing | AD6: missing | AE6: seed_companies.csv | AH6: 2026-09-08T09:01:00+00:00
A7: ROW-0007 | B7: Blauwe Hoeve | F7: Doorniksesteenweg 15 | H7: 8500 | I7: Kortrijk | W7: UNVERIFIED | Y7: 22.7 | Z7: unverified | AA7: missing | AB7: missing | AC7: missing | AD7: missing | AE7: seed_companies.csv | AH7: 2026-09-08T09:01:00+00:00
A8: ROW-0008 | B8: Frituur Natuur | H8: 8510 | I8: Marke | M8: info@frituurnatuur.be | N8: https://frituurnatuur.be/ | T8: VAT BE0629.985.405 on their receipt | W8: UNVERIFIED | Y8: 31.8 | Z8: unverified | AA8: unverified | AB8: unverified | AC8: missing | AD8: missing | AE8: seed_companies.csv | AH8: 2026-09-08T09:01:00+00:00
A9: ROW-0009 | B9: Hollywok Kortrijk | F9: President Kennedylaan 100 | H9: 8500 | I9: Kortrijk | L9: +32 56 20 55 88 | M9: info@hollywok.be | N9: https://hollywok.be/ | T9: entered twice by intern | W9: NEEDS_REVIEW | X9: duplicate group DUP-001: same phone; names 100% similar - review | Y9: 40.9 | Z9: unverified | AA9: unverified | AB9: unverified | AC9: unverified | AD9: missing | AE9: seed_companies.csv | AG9: DUP-001 | AH9: 2026-09-08T09:01:00+00:00
A10: ROW-0010 | B10: Viva Sara Kaffee | F10: Grote Markt 33 | H10: 8500 | I10: Kortrijk | L10: +32 56 21 72 70 | M10: info@vivasarakaffee.com | N10: https://vivasara.be/ | W10: NEEDS_REVIEW | X10: e-mail domain (vivasarakaffee.com) differs from website domain (vivasara.be) - review | Y10: 36.4 | Z10: unverified | AA10: unverified | AB10: unverified | AC10: unverified | AD10: missing | AE10: seed_companies.csv | AH10: 2026-09-08T09:01:00+00:00
A11: ROW-0011 | B11: Restaurant Doesnotexist | F11: Nowhere 1 | H11: ABCD | I11: Kortrijk | L11: +32 56 00 00 00 | M11: hello@this-domain-does-not-exist-9f8e7d.be | N11: https://www.this-domain-does-not-exist-9f8e7d.be/ | T11: test row: expected to be flagged | W11: NEEDS_REVIEW | X11: postcode invalid postcode for BE | Y11: 40.9 | Z11: unverified | AA11: unverified | AB11: unverified | AC11: unverified | AD11: missing | AE11: seed_companies.csv | AH11: 2026-09-08T09:01:00+00:00

Sheet Needs Review
A1: Record ID | B1: Status | C1: Company name | D1: Review flags (why) | E1: Phone | F1: E-mail | G1: Website | H1: VAT number | I1: Checks | J1: Source | K1: Source URL | L1: Resolution | M1: Resolved by | N1: Resolved on
A2: ROW-0002 | B2: NEEDS_REVIEW | C2: Hollywok | D2: duplicate group DUP-001: same phone; names 100% similar - review | E2: +32 56 20 55 88 | G2: https://hollywok.be/ | I2: company_name: unverified phone: unverified website: unverified | J2: seed_companies.csv
A3: ROW-0009 | B3: NEEDS_REVIEW | C3: Hollywok Kortrijk | D3: duplicate group DUP-001: same phone; names 100% similar - review | E3: +32 56 20 55 88 | F3: info@hollywok.be | G3: https://hollywok.be/ | I3: company_name: unverified phone: unverified email: unverified website: unverified | J3: seed_companies.csv
A4: ROW-0010 | B4: NEEDS_REVIEW | C4: Viva Sara Kaffee | D4: e-mail domain (vivasarakaffee.com) differs from website domain (vivasara.be) - review | E4: +32 56 21 72 70 | F4: info@vivasarakaffee.com | G4: https://vivasara.be/ | I4: company_name: unverified phone: unverified email: unverified website: unverified | J4: seed_companies.csv
A5: ROW-0011 | B5: NEEDS_REVIEW | C5: Restaurant Doesnotexist | D5: postcode invalid postcode for BE | E5: +32 56 00 00 00 | F5: hello@this-domain-does-not-exist-9f8e7d.be | G5: https://www.this-domain-does-not-exist-9f8e7d.be/ | I5: company_name: unverified phone: unverified email: unverified website: unverified | J5: seed_companies.csv

Sheet Duplicates
A1: Group | B1: Action | C1: Kept record | D1: Kept name | E1: Other record(s) | F1: Other name(s) | G1: Reason | H1: Name similarity % | I1: Decision
A2: DUP-001 | B2: POSSIBLE duplicate - decide | C2: ROW-0009 | D2: Hollywok Kortrijk | E2: ROW-0002 | F2: Hollywok | G2: same phone; names 100% similar | H2: 100

Sheet Run Log
A1: Run log
A3: Project | B3: seed_companies
A4: Title | B4: Quality audit of seed_companies.csv
A5: Client / requested by | B5: -
A6: Deadline | B6: -
A7: Country rules | B7: BE
A8: Schema | B8: -
A9: Started (UTC) | B9: 2026-09-08T09:01:00+00:00
A10: Tool | B10: DataHarvest 1.0.0
A11: Python | B11: 3.11.15
A12: Sources | B12: -
A13: Record limit | B13: none
A14: Records extracted | B14: 10
A15: Records delivered | B15: 10
A17: Stage | B17: Input | C17: Output | D17: Seconds | E17: Notes
A18: load | B18: 10 | C18: 10 | D18: 0 | E18: columns mapped: 8, ignored: 0
A19: normalise & validate | B19: 10 | C19: 10 | D19: 0 | E19: 2 problem(s)
A20: duplicates | B20: 10 | C20: 10 | D20: 0 | E20: 1 duplicate group(s)
A22: Warnings
A23: none
A25: Settings
A26: enrichment | B26: None
A27: verification | B27: None
A28: dedupe | B28: None

Sheet Data Dictionary
A1: Column | B1: Field key | C1: Type | D1: Required | E1: Description | F1: How it is verified
A2: Record ID | B2: record_id | C2: system | E2: Stable identifier of the row (referenced in the Duplicates and Needs Review sheets).
A3: Company name | B3: company_name | C3: string | D3: yes | E3: Trade name of the business as it presents itself publicly. | F3: Present in the primary source; confirmed when found on the company's own website.
A4: Legal entity name | B4: legal_name | C4: string | E4: Registered legal name (from the VAT register), when it differs from the trade name. | F4: Returned by the EU VIES VAT service for a valid VAT number.
A5: Category | B5: category | C5: string | E5: Main business category (e.g. restaurant, cafe, software company).
A6: Subcategory | B6: subcategory | C6: string | E6: Finer classification (e.g. cuisine type, industry).
A7: Street | B7: street | C7: string
A8: No. | B8: house_number | C8: string
A9: Postcode | B9: postcode | C9: postcode | F9: Format checked for the project country.
A10: City | B10: city | C10: string
A11: District | B11: district | C11: string | E11: Sub-municipality / neighbourhood when known.
A12: Country | B12: country | C12: string | E12: ISO 3166-1 alpha-2 code.
A13: Phone | B13: phone | C13: phone | F13: Parsed and validated with libphonenumber; confirmed when the same number appears on the website.
A14: E-mail | B14: email | C14: email | F14: Syntax check + mail-domain (MX) lookup; confirmed when found on the company's website.
A15: Website | B15: website | C15: url | F15: Fetched live; confirmed when the company name appears on the page.
A16: LinkedIn | B16: linkedin | C16: social | F16: Link found on the company's own website or supplied by the source.
A17: Facebook | B17: facebook | C17: social
A18: Instagram | B18: instagram | C18: social
A19: VAT number | B19: vat_number | C19: vat | F19: Checksum validated; existence and registered name checked with the EU VIES service.
A20: Opening hours | B20: opening_hours | C20: text
A21: Description | B21: description | C21: text
A22: Latitude | B22: latitude | C22: latitude
A23: Longitude | B23: longitude | C23: longitude
A24: Verification status | B24: status | C24: system | E24: Overall record status: VERIFIED, PARTIALLY_VERIFIED, UNVERIFIED or NEEDS_REVIEW (see Summary legend).
A25: Review flags | B25: flags | C25: system | E25: Everything a human should look at, one issue per line. Lines starting with 'note:' are informational.
A26: Completeness % | B26: completeness | C26: system | E26: Share of schema fields that have a value (required fields weigh double).
A27: Company name check | B27: check:company_name | C27: status | E27: Verification status of the field, with the reason and any other values seen in other sources.
A28: Website check | B28: check:website | C28: status | E28: Verification status of the field, with the reason and any other values seen in other sources.
A29: E-mail check | B29: check:email | C29: status | E29: Verification status of the field, with the reason and any other values seen in other sources.
A30: Phone check | B30: check:phone | C30: status | E30: Verification status of the field, with the reason and any other values seen in other sources.
A31: VAT number check | B31: check:vat_number | C31: status | E31: Verification status of the field, with the reason and any other values seen in other sources.
A32: Source | B32: source | C32: system | E32: Primary source the record was extracted from.
A33: Source URL | B33: source_url | C33: system | E33: Link to the record in the primary source, for traceability.
A34: Duplicate group | B34: duplicate_group | C34: system | E34: Set when the record was part of a duplicate cluster (see Duplicates sheet).
A35: Extracted at (UTC) | B35: extracted_at | C35: system | E35: UTC timestamp of extraction.
... A37: Reviewer notes | B37: reviewer_notes | C37: system | E37: Free text for the reviewer.
